<?xml version="1.0"?>
<robot  name='qdrone2'>
    <material name="Blue">
        <color rgba="0.0 0.0 0.8 1.0"/>
    </material>
  <link name='base_link'>
    <visual>
		  <origin xyz = "0 0 0" rpy = "0 0 0" />
      <geometry>
        <mesh filename="package://qdrone2/meshes/qdrone2_body.stl"/>
      </geometry>
    </visual>
    <inertial>
		  <origin xyz = "0 0 0" rpy = "0 0 0" />
      <mass  value = "1.51" />
      <inertia ixx  = "0.0306278" ixy = "0" ixz = "0" iyy = "0.0306278"  iyz = "0" izz =  "0.0555932" />
    </inertial>
    <collision>
        <origin rpy="0 0 0" xyz="0 0 0"/>
        <geometry>
            <mesh filename="package://qdrone2/meshes/qdrone2_body.stl" scale="0.001 0.001 0.001"/>
        </geometry>
    </collision>
  </link>
  <joint name='propellor_0_joint' type='revolute'>
    <parent link="base_link" />
    <child link ="propellor_0" />
		<origin xyz = "-0.119, 0.131, -0.02" rpy = "0 0 0" />
    <axis xyz =  "0 0 1" />
    <limit lower="-1e+16" upper="1e+16" effort="300" velocity="2"/>

  </joint>
  <link name='propellor_0'>
    <visual>
      <origin rpy="0 0 0" xyz="0 0 0"/>
      <geometry>
        <mesh filename='package://qdrone2/meshes/qdrone2_motor_prop.stl'/>
      </geometry>
      <material name="Blue"/>
    </visual>
    <inertial>
      <origin rpy="0 0 0" xyz="0 0 0"/>
      <mass value = "0.005" />
      <inertia ixx = "9.75e-07" ixy = "0" ixz = "0" iyy = "0.000166704" iyz= "0" izz = "0.000167604"/>
    </inertial>
    <collision>
      <origin rpy="0 0 0" xyz="0 0 0"/>
      <geometry>
        <mesh filename='package://qdrone2/meshes/qdrone2_motor_prop.stl'/>
      </geometry>
    </collision>
  </link>
  <joint name='propellor_1_joint' type='revolute'>
    <parent link = "base_link" />
    <child link = "propellor_1" />
		<origin xyz = "-0.119, -0.131, -0.02" rpy = "0 0 0" />
    <axis xyz= "0 0 1"/>
    <limit lower="-1e+16" upper="1e+16" effort="300" velocity="2"/>

  </joint>
  <link name='propellor_1'>
    <visual>
      <origin rpy="0 0 0" xyz="0 0 0"/>
      <geometry>
        <mesh filename='package://qdrone2/meshes/qdrone2_motor_prop.stl'/>
      </geometry>
      <material name="Blue"/>
    </visual>
    <inertial>
      <origin rpy="0 0 0" xyz="0 0 0"/>
      <mass value = "0.005" />
      <inertia
        ixx = "9.75e-07"
        ixy = "0"
        ixz = "0"
        iyy = "0.000166704"
        iyz= "0"
        izz = "0.000167604"/>
    </inertial>
    <collision>
      <origin rpy="0 0 0" xyz="0 0 0"/>
      <geometry>
        <mesh filename='package://qdrone2/meshes/qdrone2_motor_prop.stl'/>
      </geometry>
    </collision>
  </link>
  <joint name='propellor_2_joint' type='revolute'>
    <parent  link = "base_link" />
    <child  link = "propellor_2"/>
		<origin xyz = "0.116, -0.131, -0.02" rpy = "0 0 0" />
    <axis xyz= "0 0 1"/>
    <limit lower="-1e+16" upper="1e+16" effort="300" velocity="2"/>

  </joint>
  <link name='propellor_2'>
    <visual>
      <origin rpy="0 0 0" xyz="0 0 0"/>
      <geometry>
        <mesh filename='package://qdrone2/meshes/qdrone2_motor_prop.stl'/>
      </geometry>
      <material name="Blue"/>
    </visual>
    <inertial>
      <origin rpy="0 0 0" xyz="0 0 0"/>
      <mass value = "0.005" />
      <inertia
        ixx = "9.75e-07"
        ixy = "0"
        ixz = "0"
        iyy = "0.000166704"
        iyz= "0"
        izz = "0.000167604"/>
    </inertial>
    <collision>
      <origin rpy="0 0 0" xyz="0 0 0"/>
      <geometry>
        <mesh filename='package://qdrone2/meshes/qdrone2_motor_prop.stl'/>
      </geometry>
    </collision>
  </link>
  <joint name='propellor_3_joint' type='revolute'>
    <parent link = "base_link"/>
    <child link = "propellor_3"/>
		<origin xyz = "0.116, 0.131, -0.02" rpy = "0 0 0" />
    <axis xyz= "0 0 1"/>
    <limit lower="-1e+16" upper="1e+16" effort="300" velocity="2"/>
  </joint>
  <link name='propellor_3'>
    <visual>
      <origin rpy="0 0 0" xyz="0 0 0"/>
      <geometry>
        <mesh filename='package://qdrone2/meshes/qdrone2_motor_prop.stl'/>
      </geometry>
      <material name="Blue"/>
    </visual>
    <inertial>
      <origin rpy="0 0 0" xyz="0 0 0"/>
      <mass value = "0.005" />
      <inertia
        ixx = "9.75e-07"
        ixy = "0"
        ixz = "0"
        iyy = "0.000166704"
        iyz= "0"
        izz = "0.000167604"/>
    </inertial>
    <collision>
      <origin rpy="0 0 0" xyz="0 0 0"/>
      <geometry>
        <mesh filename='package://qdrone2/meshes/qdrone2_motor_prop.stl'/>
      </geometry>
    </collision>
  </link>
  <!-- <frame name='base_joint' attached_to='base_link'>
    <pose>0 0 0 0 -0 0</pose>
  </frame>
  <frame name='base_link_inertia' attached_to='base_joint'/> -->
</robot>
